<?xml version="1.0" encoding="UTF-8"?>
<robot xmlns:xacro="http://www.ros.org/wiki/xacro">
<!-- Import Rviz colors -->
<xacro:include filename="$(find poppy_description)/urdf/poppy.material.xacro" />

<xacro:macro name="poppy" params="parent *origin">
  <joint name="origin_to_link1" type="fixed">
    <xacro:insert_block name="origin" />
    <parent link="${parent}" />
    <child link="base_link" />
    <axis xyz="0 0 1" />
  </joint>

<!-- Base link -->
  <link name="base_link">
    <visual>
      <origin xyz="0 0 0" rpy="0 0 0" />
      <geometry>
        <mesh filename="package://poppy_description/meshes/base.dae" />
      </geometry>
      <material name="darkgrey"/>
    </visual>
    <collision>
      <origin xyz="0 0.038 0.015" rpy="0 0 0" />
      <geometry>
        <cylinder length="0.03" radius="0.08" />
      </geometry>
    </collision>
  </link>
<!-- Motor 1 -->
  <joint name="m1" type="revolute">
    <origin xyz="0 0 0.0327993216120967" rpy="0 0 0" />
    <parent link="base_link" />
    <child link="link1" />
    <axis xyz="0 0 1" />
    <limit velocity="1" effort="0.3" lower="${-150*(pi/180)}" upper="${150*(pi/180)}" />
  </joint>
<!-- Link 1 -->
  <link name="link1">
    <visual>
      <origin xyz="0 0 0" rpy="0 0 0" />
      <geometry>
        <mesh filename="package://poppy_description/meshes/long_U.dae" />
      </geometry>
      <material name="darkgrey"/>
    </visual>
    <collision>
      <origin xyz="0 0 0.01" rpy="0 0 0" />
      <geometry>
        <cylinder length="0.02" radius="0.02" />
      </geometry>
    </collision>
    <inertial>
      <mass value="0.1" />
      <inertia ixx="0.03" iyy="0.03" izz="0.03" ixy="0.0" ixz="0.0" iyz="0.0" />
    </inertial>
  </link>
<!-- Motor 2 -->
  <joint name="m2" type="revolute">
    <origin xyz="0 0 0.0240006783879033" rpy="0 -1.5707963267949 0" />
    <parent link="link1" />
    <child link="link2" />
    <axis xyz="0 0 -1" />
    <limit velocity="1" effort="0.3" lower="${-150*(pi/180)}" upper="${150*(pi/180)}" />
  </joint>
<!-- link2 -->
  <link name="link2">
    <visual>
      <origin xyz="0 0 0" rpy="0 1.5707963267949 0" />
      <geometry>
        <mesh filename="package://poppy_description/meshes/section_1.dae" />
      </geometry>
      <material name="darkgrey"/>
    </visual>
    <collision>
      <origin xyz="0.025 0 0" rpy="0 1.5707963267949 0" />
      <geometry>
        <cylinder length="0.05" radius="0.02" />
      </geometry>
    </collision>
    <inertial>
      <mass value="0.1" />
      <inertia ixx="0.03" iyy="0.03" izz="0.03" ixy="0.0" ixz="0.0" iyz="0.0" />
    </inertial>
  </link>
<!-- Motor 3 -->
  <joint name="m3" type="revolute">
    <origin xyz="0.054 0 0" rpy="0 0 0" />
    <parent link="link2" />
    <child link="link3" />
    <axis xyz="0 0 -1" />
<limit velocity="1" effort="0.3" lower="${-150*(pi/180)}" upper="${150*(pi/180)}" />
  </joint>
<!-- link3 -->
  <link name="link3">
    <visual>
      <origin xyz="0 0 0" rpy="0 1.5707963267949 0" />
      <geometry>
        <mesh filename="package://poppy_description/meshes/section_2.dae" />
      </geometry>
      <material name="darkgrey"/>
    </visual>
    <collision>
      <origin xyz="0.025 0 0" rpy="0 1.5707963267949 0" />
      <geometry>
        <cylinder length="0.05" radius="0.02" />
      </geometry>
    </collision>
    <inertial>
      <mass value="0.1" />
      <inertia ixx="0.03" iyy="0.03" izz="0.03" ixy="0.0" ixz="0.0" iyz="0.0" />
    </inertial>
  </link>
<!-- Motor 4 -->
  <joint name="m4" type="revolute">
    <origin xyz="0.045 0 0" rpy="0 -1.5707963267949 0" />
    <parent link="link3" />
    <child link="link4" />
    <axis xyz="0 0 -1" />
<limit velocity="1" effort="0.3" lower="${-150*(pi/180)}" upper="${150*(pi/180)}" />
  </joint>
<!-- link4 -->
  <link name="link4">
    <visual>
      <origin xyz="0 0 0" rpy="0 3.14159268 0" />
      <geometry>
        <mesh filename="package://poppy_description/meshes/section_3.dae" />
      </geometry>
      <material name="darkgrey"/>
    </visual>
    <collision>
      <origin xyz="0 -0.025 0" rpy="1.5707963267949 0 0" />
      <geometry>
        <cylinder length="0.05" radius="0.02" />
      </geometry>
    </collision>
    <inertial>
      <mass value="0.1" />
      <inertia ixx="0.03" iyy="0.03" izz="0.03" ixy="0.0" ixz="0.0" iyz="0.0" />
    </inertial>
  </link>
<!-- Motor 5 -->
  <joint name="m5" type="revolute">
    <origin xyz="0 -0.048 0" rpy="0 -1.5707963267949 0" />
    <parent link="link4" />
    <child link="link5" />
    <axis xyz="0 0 1" />
<limit velocity="1" effort="0.3" lower="${-150*(pi/180)}" upper="${150*(pi/180)}" />
  </joint>
<!-- link5 -->
  <link name="link5">
    <visual>
      <origin xyz="0 -0.058 0" rpy="0 -1.5707963267949 0" />
      <geometry>
        <mesh filename="package://poppy_description/meshes/section_4.dae" />
      </geometry>
      <material name="darkgrey"/>
    </visual>
    <collision>
      <origin xyz="0 -0.035 0" rpy="1.5707963267949 0 0" />
      <geometry>
        <cylinder length="0.06" radius="0.02" />
        <box size="0.05 0.02 0.03" />
      </geometry>
    </collision>
    <inertial>
      <mass value="0.1" />
      <inertia ixx="0.03" iyy="0.03" izz="0.03" ixy="0.0" ixz="0.0" iyz="0.0" />
    </inertial>
  </link>
<!-- gripper -->
  <link name="gripper">
    <visual>
      <origin xyz="0 0 0" rpy="0 0 0" />
      <geometry>
      <mesh filename="package://poppy_description/meshes/gripper.dae" />
      </geometry>
      <material name="darkgrey"/>
    </visual>
    <collision>
      <origin xyz="0 -0.04 0" rpy="-1.5707963267949 0 0" />
      <geometry>
        <cylinder length="0.06" radius="0.02" />
      </geometry>
    </collision>
    <inertial>
      <mass value="0.1" />
      <inertia ixx="0.03" iyy="0.03" izz="0.03" ixy="0.0" ixz="0.0" iyz="0.0" />
    </inertial>
  </link>
<!-- Motor 6 -->
  <joint name="m6" type="revolute">
    <origin xyz="0 -0.058 0" rpy="0 -1.5707963267949 0" />
    <axis xyz="0 0 -1" />
    <parent link="link5" />
    <child link="gripper" />
    <limit velocity="1" effort="0.3" lower="${-150*(pi/180)}" upper="${150*(pi/180)}" />
  </joint>
<!-- Moving tip of gripper -->
  <link name="moving_tip" />
  <joint name="t7m" type="fixed">
    <origin xyz="0 -0.052 0" rpy="-1.5707963267949 0 0" />
    <parent link="gripper" />
    <child link="moving_tip" />
  </joint>
</xacro:macro>
</robot>