<?xml version="1.0" ?>
<!-- =================================================================================== -->
<!-- |    This document was autogenerated by xacro from poppy.urdf.xacro               | -->
<!-- |    EDITING THIS FILE BY HAND IS NOT RECOMMENDED                                 | -->
<!-- =================================================================================== -->
<robot name="poppy">
  <material name="black">
    <color rgba="0.0 0.0 0.0 1.0"/>
  </material>
  <material name="white">
    <color rgba="1.0 1.0 1.0 1.0"/>
  </material>
  <material name="red">
    <color rgba="0.8 0.0 0.0 1.0"/>
  </material>
  <material name="blue">
    <color rgba="0.0 0.0 0.8 1.0"/>
  </material>
  <material name="green">
    <color rgba="0.0 0.8 0.0 1.0"/>
  </material>
  <material name="grey">
    <color rgba="0.5 0.5 0.5 1.0"/>
  </material>
  <material name="darkgrey">
    <color rgba="0.752941176470588 0.752941176470588 0.752941176470588 1"/>
  </material>
  <link name="world"/>
  <joint name="origin_to_link1" type="fixed">
    <origin rpy="0 0 0" xyz="0 0 0"/>
    <parent link="world"/>
    <child link="base_link"/>
    <axis xyz="0 0 1"/>
  </joint>
  <!-- Base link -->
  <link name="base_link">
    <visual>
      <origin rpy="0 0 0" xyz="0 0 0"/>
      <geometry>
        <mesh filename="package://poppy_description/meshes/base.dae"/>
      </geometry>
      <material name="darkgrey"/>
    </visual>
    <collision>
      <origin rpy="0 0 0" xyz="0 0.038 0.015"/>
      <geometry>
        <cylinder length="0.03" radius="0.08"/>
      </geometry>
    </collision>
  </link>
  <!-- Motor 1 -->
  <joint name="m1" type="revolute">
    <origin rpy="0 0 0" xyz="0 0 0.0327993216120967"/>
    <parent link="base_link"/>
    <child link="link1"/>
    <axis xyz="0 0 1"/>
    <limit effort="1" lower="-2.6179938779914944" upper="2.6179938779914944" velocity="10"/>
  </joint>
  <!-- Link 1 -->
  <link name="link1">
    <visual>
      <origin rpy="0 0 0" xyz="0 0 0"/>
      <geometry>
        <mesh filename="package://poppy_description/meshes/long_U.dae"/>
      </geometry>
      <material name="darkgrey"/>
    </visual>
    <collision>
      <origin rpy="0 0 0" xyz="0 0 0.01"/>
      <geometry>
        <cylinder length="0.02" radius="0.02"/>
      </geometry>
    </collision>
    <inertial>
      <mass value="0.1"/>
      <inertia ixx="0.03" ixy="0.0" ixz="0.0" iyy="0.03" iyz="0.0" izz="0.03"/>
    </inertial>
  </link>
  <!-- Motor 2 -->
  <joint name="m2" type="revolute">
    <origin rpy="0 -1.5707963267949 0" xyz="0 0 0.0240006783879033"/>
    <parent link="link1"/>
    <child link="link2"/>
    <axis xyz="0 0 1"/>
    <limit effort="1" lower="-2.6179938779914944" upper="2.6179938779914944" velocity="10"/>
  </joint>
  <!-- link2 -->
  <link name="link2">
    <visual>
      <origin rpy="0 1.5707963267949 0" xyz="0 0 0"/>
      <geometry>
        <mesh filename="package://poppy_description/meshes/section_1.dae"/>
      </geometry>
      <material name="darkgrey"/>
    </visual>
    <collision>
      <origin rpy="0 1.5707963267949 0" xyz="0.025 0 0"/>
      <geometry>
        <cylinder length="0.05" radius="0.02"/>
      </geometry>
    </collision>
    <inertial>
      <mass value="0.1"/>
      <inertia ixx="0.03" ixy="0.0" ixz="0.0" iyy="0.03" iyz="0.0" izz="0.03"/>
    </inertial>
  </link>
  <!-- Motor 3 -->
  <joint name="m3" type="revolute">
    <origin rpy="0 0 0" xyz="0.054 0 0"/>
    <parent link="link2"/>
    <child link="link3"/>
    <axis xyz="0 0 1"/>
    <limit effort="1" lower="-2.6179938779914944" upper="2.6179938779914944" velocity="10"/>
  </joint>
  <!-- link3 -->
  <link name="link3">
    <visual>
      <origin rpy="0 1.5707963267949 0" xyz="0 0 0"/>
      <geometry>
        <mesh filename="package://poppy_description/meshes/section_2.dae"/>
      </geometry>
      <material name="darkgrey"/>
    </visual>
    <collision>
      <origin rpy="0 1.5707963267949 0" xyz="0.025 0 0"/>
      <geometry>
        <cylinder length="0.05" radius="0.02"/>
      </geometry>
    </collision>
    <inertial>
      <mass value="0.1"/>
      <inertia ixx="0.03" ixy="0.0" ixz="0.0" iyy="0.03" iyz="0.0" izz="0.03"/>
    </inertial>
  </link>
  <!-- Motor 4 -->
  <joint name="m4" type="revolute">
    <origin rpy="0 -1.5707963267949 0" xyz="0.045 0 0"/>
    <parent link="link3"/>
    <child link="link4"/>
    <axis xyz="0 0 -1"/>
    <limit effort="1" lower="-2.6179938779914944" upper="2.6179938779914944" velocity="10"/>
  </joint>
  <!-- link4 -->
  <link name="link4">
    <visual>
      <origin rpy="0 3.14159268 0" xyz="0 0 0"/>
      <geometry>
        <mesh filename="package://poppy_description/meshes/section_3.dae"/>
      </geometry>
      <material name="darkgrey"/>
    </visual>
    <collision>
      <origin rpy="1.5707963267949 0 0" xyz="0 -0.025 0"/>
      <geometry>
        <cylinder length="0.05" radius="0.02"/>
      </geometry>
    </collision>
    <inertial>
      <mass value="0.1"/>
      <inertia ixx="0.03" ixy="0.0" ixz="0.0" iyy="0.03" iyz="0.0" izz="0.03"/>
    </inertial>
  </link>
  <!-- Motor 5 -->
  <joint name="m5" type="revolute">
    <origin rpy="0 -1.5707963267949 0" xyz="0 -0.048 0"/>
    <parent link="link4"/>
    <child link="link5"/>
    <axis xyz="0 0 -1"/>
    <limit effort="1" lower="-2.6179938779914944" upper="2.6179938779914944" velocity="10"/>
  </joint>
  <!-- link5 -->
  <link name="link5">
    <visual>
      <origin rpy="0 -1.5707963267949 0" xyz="0 -0.058 0"/>
      <geometry>
        <mesh filename="package://poppy_description/meshes/section_4.dae"/>
      </geometry>
      <material name="darkgrey"/>
    </visual>
    <collision>
      <origin rpy="1.5707963267949 0 0" xyz="0 -0.035 0"/>
      <geometry>
        <cylinder length="0.06" radius="0.02"/>
        <box size="0.05 0.02 0.03"/>
      </geometry>
    </collision>
    <inertial>
      <mass value="0.1"/>
      <inertia ixx="0.03" ixy="0.0" ixz="0.0" iyy="0.03" iyz="0.0" izz="0.03"/>
    </inertial>
  </link>
  <!-- gripper -->
  <link name="gripper">
    <visual>
      <origin rpy="0 0 0" xyz="0 0 0"/>
      <geometry>
        <mesh filename="package://poppy_description/meshes/gripper.dae"/>
      </geometry>
      <material name="darkgrey"/>
    </visual>
    <collision>
      <origin rpy="-1.5707963267949 0 0" xyz="0 -0.04 0"/>
      <geometry>
        <cylinder length="0.06" radius="0.02"/>
      </geometry>
    </collision>
    <inertial>
      <mass value="0.1"/>
      <inertia ixx="0.03" ixy="0.0" ixz="0.0" iyy="0.03" iyz="0.0" izz="0.03"/>
    </inertial>
  </link>
  <!-- Motor 6 -->
  <joint name="m6" type="revolute">
    <origin rpy="0 -1.5707963267949 0" xyz="0 -0.058 0"/>
    <axis xyz="0 0 1"/>
    <parent link="link5"/>
    <child link="gripper"/>
    <limit effort="1" lower="-1.5707963267948966" upper="0.5235987755982988" velocity="10"/>
  </joint>
  <!-- Moving tip of gripper -->
  <link name="moving_tip"/>
  <joint name="t7m" type="fixed">
    <origin rpy="-1.5707963267949 0 0" xyz="0 -0.052 0"/>
    <parent link="gripper"/>
    <child link="moving_tip"/>
  </joint>
  <ros2_control name="poppy_ros2_control" type="system">
    <hardware>
      <plugin>dynamixel_hardware/DynamixelHardware</plugin>
      <param name="usb_port">/dev/ttyUSB0</param>
      <param name="baud_rate">115200</param>
      <!--<param name="use_dummy">true</param>-->
    </hardware>
    <joint name="m1">
      <param name="id">1</param>
      <command_interface initial_value="0.0" name="position"/>
      <!--command_interface name="velocity"/-->
      <state_interface name="position"/>
      <state_interface name="velocity"/>
      <!--state_interface name="effort"/-->
    </joint>
    <joint name="m2">
      <param name="id">2</param>
      <command_interface initial_value="0.0" name="position"/>
      <!--command_interface name="velocity"/-->
      <state_interface name="position"/>
      <state_interface name="velocity"/>
      <!--state_interface name="effort"/-->
    </joint>
    <joint name="m3">
      <param name="id">3</param>
      <command_interface initial_value="0.0" name="position"/>
      <!--command_interface name="velocity"/-->
      <state_interface name="position"/>
      <state_interface name="velocity"/>
      <!--state_interface name="effort"/-->
    </joint>
    <joint name="m4">
      <param name="id">4</param>
      <command_interface initial_value="0.0" name="position"/>
      <!--command_interface name="velocity"/-->
      <state_interface name="position"/>
      <state_interface name="velocity"/>
      <!--state_interface name="effort"/-->
    </joint>
    <joint name="m5">
      <param name="id">5</param>
      <command_interface initial_value="0.0" name="position"/>
      <!--command_interface name="velocity"/-->
      <state_interface name="position"/>
      <state_interface name="velocity"/>
      <!--state_interface name="effort"/-->
    </joint>
    <joint name="m6">
      <param name="id">6</param>
      <command_interface initial_value="0.0" name="position"/>
      <!--command_interface name="velocity"/-->
      <state_interface name="position"/>
      <state_interface name="velocity"/>
      <!--state_interface name="effort"/-->
    </joint>
  </ros2_control>
</robot>
